Workbook
Name AFNORX44101: Classification!$L$1:$L$6
Name Arrant: [1]Sheet2Form2!$B$2:$B$12
Name Arrant: [2]Sheet2Form2!$B$2:$B$12
Name Arrant: Classification!$B$2:$B$12
Name Arrant: [3]Sheet2Form2!$B$2:$B$12
Name BS_5295: Classification!$J$1:$J$7
Name Class_Air_Changes: 'Class Air Changes'!$D$5:$F$75
Name EUGMP: Classification!$G$1:$G$5
Name FDA: Classification!$D$1:$D$7
Name GERMANY_VD: Classification!$K$1:$K$9
Name GMP: Classification!$E$1:$E$5
Name ISO_14644: Classification!$C1:$C10
Name JIS_B_9920: Classification!$F$1:$F$10
Name NC__Non_Classified: Classification!$M$1:$M$9
Name NC_Non_Classified: Classification!$M$1:$M$9
Name Standards: Table1[#All]
Name TGA: Classification!$I$1:$I$7
Name WHO: Classification!$H$1:$H$8

Sheet Class Air Changes
C5: STANDARDS | D5: CLASSIFICATION | E5: NO.AIR CH/HR | G5: Term. Filter Coverage | K5: Standard/Class | L5: ACH Range | M5: Notes
C6: ISO 14644-4 | D6: ISO 9 | E6: 5 | F6: 15 | G6: 0.05 | H6: 0.15 | K6: ISO 14644-1 Class 1 | L6: 500–750 | M6: Ultra-clean (semiconductors)
C7: ISO 14644-4 | D7: ISO 8 | E7: 20 | F7: 60 | G7: 0.05 | H7: 0.15 | K7: ISO 14644-1 Class 2–3 | L7: 500–750
C8: ISO 14644-4 | D8: ISO 7 | E8: 60 | F8: 150 | G8: 0.15 | H8: 0.25 | K8: ISO 14644-1 Class 4 | L8: 400–750
C9: ISO 14644-4 | D9: ISO 6 | E9: 150 | F9: 240 | G9: 0.25 | H9: 0.4 | K9: ISO 14644-1 Class 5 | L9: 240–600 | M9: Sterile manufacturing
C10: ISO 14644-4 | D10: ISO 5 | E10: 240 | F10: 500 | G10: 0.35 | H10: 0.7 | K10: ISO 14644-1 Class 6 | L10: 150–240
C11: ISO 14644-4 | D11: ISO 4 | E11: 300 | F11: 600 | G11: 0.5 | H11: 0.9 | K11: ISO 14644-1 Class 7 | L11: 60–150
C12: ISO 14644-4 | D12: ISO 3 | E12: 400 | F12: 750 | G12: 0.6 | H12: 1 | K12: ISO 14644-1 Class 8 | L12: 10–25
C13: ISO 14644-4 | D13: ISO 2 | E13: 500 | F13: 750 | G13: 0.8 | H13: 1 | K13: ISO 14698 | L13: 20–40 | M13: Biocontamination control
C14: ISO 14644-4 | D14: ISO 1 | E14: 500 | F14: 750 | G14: 0.8 | H14: 1 | K14: BS 5295 Class 1–4 | L14: 240–600
C15: FDA 209E | D15: Class100K | E15: 12 | F15: 25 | K15: AFNOR NF S 90-351 | L15: 20–240 | M15: French standard
C16: FDA 209E | D16: Class10K | E16: 30 | F16: 60 | K16: TGA (Australia) | L16: 240–600 | M16: Based on ISO/GMP
C17: FDA 209E | D17: Class1K | E17: 80 | F17: 130 | K17: WHO GMP Grades A–D | L17: 20–240 | M17: A–D grades
C18: FDA 209E | D18: Class 100 | E18: 150 | F18: 300 | K18: JIS B 9920 (Japan) | L18: 10–600 | M18: Similar to ISO
C19: FDA 209E | D19: Class 10 | E19: 180 | F19: 400 | K19: FDA (US) | L19: 240–600 | M19: Follows ISO/GMP
C20: FDA 209E | D20: Class 1 | E20: 240 | F20: 500 | K20: EU GMP Grades A–D | L20: 20–240 | M20: Grades A–D
C21: GMP | D21: Grade D (ISO 8 at Rest & Not Defined) | E21: 20 | F21: 40 | K21: Germany VDI 2083 | L21: 20–600 | M21: Engineering guideline
C22: GMP | D22: Grade C (ISO 7 at Rest & ISO 8 in Oper.) | E22: 60 | F22: 120
C23: GMP | D23: Grade B (ISO 5 at Rest & ISO 7 in Oper.) | E23: 120 | F23: 180
C24: GMP | D24: Grade A (ISO 5 at Rest & ISO 5 in Oper.) | E24: 180 | F24: 240
C25: JIS B 9920 | D25: JIS Class 9 | E25: 10 | F25: 20
C26: JIS B 9920 | D26: JIS Class 8 | E26: 20 | F26: 60
C27: JIS B 9920 | D27: JIS Class 7 | E27: 60 | F27: 120
C28: JIS B 9920 | D28: JIS Class 6 | E28: 120 | F28: 180
C29: JIS B 9920 | D29: JIS Class 5 | E29: 180 | F29: 240
C30: JIS B 9920 | D30: JIS Class 4 | E30: 240 | F30: 350
C31: JIS B 9920 | D31: JIS Class 3 | E31: 350 | F31: 500
C32: JIS B 9920 | D32: JIS Class 2 | E32: 400 | F32: 600
C33: JIS B 9920 | D33: JIS Class 1 | E33: 400 | F33: 600
... C37: EU GMP | D37: Grade A (ISO 5 at Rest & ISO 5 in Oper.) | E37: 180 | F37: 240
C38: TGA | D38: 3500 | E38: 15 | F38: 40
C39: TGA | D39: 350 | E39: 40 | F39: 80
C40: TGA | D40: 35 | E40: 80 | F40: 130
C41: TGA | D41: 3.5 | E41: 130 | F41: 300
C42: TGA | D42: 0.35 | E42: 180 | F42: 400
C43: TGA | D43: 0.035 | E43: 240 | F43: 500
C44: BS 5295 | D44: K | E44: 12 | F44: 25
C45: BS 5295 | D45: J | E45: 30 | F45: 80
C46: BS 5295 | D46: G or H | E46: 120 | F46: 180
C47: BS 5295 | D47: E or F | E47: 240 | F47: 350
...

Sheet Sheet1
A1: STANDARDS | B1: CLASSIFICATION | C1: NO.AIR CH/HR
A2: ISO 14644-4 | B2: ISO 9 | C2: 5 | D2: 15 | E2: ="INSERT INTO tCR_metadata (standard_name, classification_name, acph_min, acph_max) VALUES ('"&A2&"', '"&B2&"', "&C2&", "&D2&");" -> INSERT INTO tCR_metadata (standard_name, classification_name, acph_min, acph_max) VALUES ('ISO 14644-4', 'ISO 9', 5, 15);
A3: ISO 14644-4 | B3: ISO 8 | C3: 20 | D3: 60 | E3: ="INSERT INTO tCR_metadata (standard_name, classification_name, acph_min, acph_max) VALUES ('"&A3&"', '"&B3&"', "&C3&", "&D3&");" -> INSERT INTO tCR_metadata (standard_name, classification_name, acph_min, acph_max) VALUES ('ISO 14644-4', 'ISO 8', 20, 60);
A4: ISO 14644-4 | B4: ISO 7 | C4: 60 | D4: 150 | E4: ="INSERT INTO tCR_metadata (standard_name, classification_name, acph_min, acph_max) VALUES ('"&A4&"', '"&B4&"', "&C4&", "&D4&");" -> INSERT INTO tCR_metadata (standard_name, classification_name, acph_min, acph_max) VALUES ('ISO 14644-4', 'ISO 7', 60, 150);
A5: ISO 14644-4 | B5: ISO 6 | C5: 150 | D5: 240 | E5: ="INSERT INTO tCR_metadata (standard_name, classification_name, acph_min, acph_max) VALUES ('"&A5&"', '"&B5&"', "&C5&", "&D5&");" -> INSERT INTO tCR_metadata (standard_name, classification_name, acph_min, acph_max) VALUES ('ISO 14644-4', 'ISO 6', 150, 240);
A6: ISO 14644-4 | B6: ISO 5 | C6: 240 | D6: 500 | E6: ="INSERT INTO tCR_metadata (standard_name, classification_name, acph_min, acph_max) VALUES ('"&A6&"', '"&B6&"', "&C6&", "&D6&");" -> INSERT INTO tCR_metadata (standard_name, classification_name, acph_min, acph_max) VALUES ('ISO 14644-4', 'ISO 5', 240, 500);
A7: ISO 14644-4 | B7: ISO 4 | C7: 300 | D7: 600 | E7: ="INSERT INTO tCR_metadata (standard_name, classification_name, acph_min, acph_max) VALUES ('"&A7&"', '"&B7&"', "&C7&", "&D7&");" -> INSERT INTO tCR_metadata (standard_name, classification_name, acph_min, acph_max) VALUES ('ISO 14644-4', 'ISO 4', 300, 600);
A8: ISO 14644-4 | B8: ISO 3 | C8: 400 | D8: 750 | E8: ="INSERT INTO tCR_metadata (standard_name, classification_name, acph_min, acph_max) VALUES ('"&A8&"', '"&B8&"', "&C8&", "&D8&");" -> INSERT INTO tCR_metadata (standard_name, classification_name, acph_min, acph_max) VALUES ('ISO 14644-4', 'ISO 3', 400, 750);
A9: ISO 14644-4 | B9: ISO 2 | C9: 500 | D9: 750 | E9: ="INSERT INTO tCR_metadata (standard_name, classification_name, acph_min, acph_max) VALUES ('"&A9&"', '"&B9&"', "&C9&", "&D9&");" -> INSERT INTO tCR_metadata (standard_name, classification_name, acph_min, acph_max) VALUES ('ISO 14644-4', 'ISO 2', 500, 750);
A10: ISO 14644-4 | B10: ISO 1 | C10: 500 | D10: 750 | E10: ="INSERT INTO tCR_metadata (standard_name, classification_name, acph_min, acph_max) VALUES ('"&A10&"', '"&B10&"', "&C10&", "&D10&");" -> INSERT INTO tCR_metadata (standard_name, classification_name, acph_min, acph_max) VALUES ('ISO 14644-4', 'ISO 1', 500, 750);
A11: FDA 209E | B11: Class100K | C11: 12 | D11: 25 | E11: ="INSERT INTO tCR_metadata (standard_name, classification_name, acph_min, acph_max) VALUES ('"&A11&"', '"&B11&"', "&C11&", "&D11&");" -> INSERT INTO tCR_metadata (standard_name, classification_name, acph_min, acph_max) VALUES ('FDA 209E', 'Class100K', 12, 25);
A12: FDA 209E | B12: Class10K | C12: 30 | D12: 60 | E12: ="INSERT INTO tCR_metadata (standard_name, classification_name, acph_min, acph_max) VALUES ('"&A12&"', '"&B12&"', "&C12&", "&D12&");" -> INSERT INTO tCR_metadata (standard_name, classification_name, acph_min, acph_max) VALUES ('FDA 209E', 'Class10K', 30, 60);
A13: FDA 209E | B13: Class1K | C13: 80 | D13: 130 | E13: ="INSERT INTO tCR_metadata (standard_name, classification_name, acph_min, acph_max) VALUES ('"&A13&"', '"&B13&"', "&C13&", "&D13&");" -> INSERT INTO tCR_metadata (standard_name, classification_name, acph_min, acph_max) VALUES ('FDA 209E', 'Class1K', 80, 130);
... A33: EU GMP | B33: Grade A (ISO 5 at Rest & ISO 5 in Oper.) | C33: 180 | D33: 240 | E33: ="INSERT INTO tCR_metadata (standard_name, classification_name, acph_min, acph_max) VALUES ('"&A33&"', '"&B33&"', "&C33&", "&D33&");" -> INSERT INTO tCR_metadata (standard_name, classification_name, acph_min, acph_max) VALUES ('EU GMP', 'Grade A (ISO 5 at Rest & ISO 5 in Oper.)', 180, 240);
A34: TGA | B34: 3500 | C34: 15 | D34: 40 | E34: ="INSERT INTO tCR_metadata (standard_name, classification_name, acph_min, acph_max) VALUES ('"&A34&"', '"&B34&"', "&C34&", "&D34&");" -> INSERT INTO tCR_metadata (standard_name, classification_name, acph_min, acph_max) VALUES ('TGA', '3500', 15, 40);
A35: TGA | B35: 350 | C35: 40 | D35: 80 | E35: ="INSERT INTO tCR_metadata (standard_name, classification_name, acph_min, acph_max) VALUES ('"&A35&"', '"&B35&"', "&C35&", "&D35&");" -> INSERT INTO tCR_metadata (standard_name, classification_name, acph_min, acph_max) VALUES ('TGA', '350', 40, 80);
A36: TGA | B36: 35 | C36: 80 | D36: 130 | E36: ="INSERT INTO tCR_metadata (standard_name, classification_name, acph_min, acph_max) VALUES ('"&A36&"', '"&B36&"', "&C36&", "&D36&");" -> INSERT INTO tCR_metadata (standard_name, classification_name, acph_min, acph_max) VALUES ('TGA', '35', 80, 130);
A37: TGA | B37: 3.5 | C37: 130 | D37: 300 | E37: ="INSERT INTO tCR_metadata (standard_name, classification_name, acph_min, acph_max) VALUES ('"&A37&"', '"&B37&"', "&C37&", "&D37&");" -> INSERT INTO tCR_metadata (standard_name, classification_name, acph_min, acph_max) VALUES ('TGA', '3.5', 130, 300);
A38: TGA | B38: 0.35 | C38: 180 | D38: 400 | E38: ="INSERT INTO tCR_metadata (standard_name, classification_name, acph_min, acph_max) VALUES ('"&A38&"', '"&B38&"', "&C38&", "&D38&");" -> INSERT INTO tCR_metadata (standard_name, classification_name, acph_min, acph_max) VALUES ('TGA', '0.35', 180, 400);
A39: TGA | B39: 0.035 | C39: 240 | D39: 500 | E39: ="INSERT INTO tCR_metadata (standard_name, classification_name, acph_min, acph_max) VALUES ('"&A39&"', '"&B39&"', "&C39&", "&D39&");" -> INSERT INTO tCR_metadata (standard_name, classification_name, acph_min, acph_max) VALUES ('TGA', '0.035', 240, 500);
A40: BS 5295 | B40: K | C40: 12 | D40: 25 | E40: ="INSERT INTO tCR_metadata (standard_name, classification_name, acph_min, acph_max) VALUES ('"&A40&"', '"&B40&"', "&C40&", "&D40&");" -> INSERT INTO tCR_metadata (standard_name, classification_name, acph_min, acph_max) VALUES ('BS 5295', 'K', 12, 25);
A41: BS 5295 | B41: J | C41: 30 | D41: 80 | E41: ="INSERT INTO tCR_metadata (standard_name, classification_name, acph_min, acph_max) VALUES ('"&A41&"', '"&B41&"', "&C41&", "&D41&");" -> INSERT INTO tCR_metadata (standard_name, classification_name, acph_min, acph_max) VALUES ('BS 5295', 'J', 30, 80);
A42: BS 5295 | B42: G or H | C42: 120 | D42: 180 | E42: ="INSERT INTO tCR_metadata (standard_name, classification_name, acph_min, acph_max) VALUES ('"&A42&"', '"&B42&"', "&C42&", "&D42&");" -> INSERT INTO tCR_metadata (standard_name, classification_name, acph_min, acph_max) VALUES ('BS 5295', 'G or H', 120, 180);
A43: BS 5295 | B43: E or F | C43: 240 | D43: 350 | E43: ="INSERT INTO tCR_metadata (standard_name, classification_name, acph_min, acph_max) VALUES ('"&A43&"', '"&B43&"', "&C43&", "&D43&");" -> INSERT INTO tCR_metadata (standard_name, classification_name, acph_min, acph_max) VALUES ('BS 5295', 'E or F', 240, 350);
A44: BS 5295 | B44: D | C44: 350 | D44: 600 | E44: ="INSERT INTO tCR_metadata (standard_name, classification_name, acph_min, acph_max) VALUES ('"&A44&"', '"&B44&"', "&C44&", "&D44&");" -> INSERT INTO tCR_metadata (standard_name, classification_name, acph_min, acph_max) VALUES ('BS 5295', 'D', 350, 600);
A45: BS 5295 | B45: C | C45: 400 | D45: 600 | E45: ="INSERT INTO tCR_metadata (standard_name, classification_name, acph_min, acph_max) VALUES ('"&A45&"', '"&B45&"', "&C45&", "&D45&");" -> INSERT INTO tCR_metadata (standard_name, classification_name, acph_min, acph_max) VALUES ('BS 5295', 'C', 400, 600);
A46: GERMANY VD | B46: 6 | C46: 20 | D46: 60 | E46: ="INSERT INTO tCR_metadata (standard_name, classification_name, acph_min, acph_max) VALUES ('"&A46&"', '"&B46&"', "&C46&", "&D46&");" -> INSERT INTO tCR_metadata (standard_name, classification_name, acph_min, acph_max) VALUES ('GERMANY VD', '6', 20, 60);
A47: GERMANY VD | B47: 5 | C47: 60 | D47: 120 | E47: ="INSERT INTO tCR_metadata (standard_name, classification_name, acph_min, acph_max) VALUES ('"&A47&"', '"&B47&"', "&C47&", "&D47&");" -> INSERT INTO tCR_metadata (standard_name, classification_name, acph_min, acph_max) VALUES ('GERMANY VD', '5', 60, 120);
A48: GERMANY VD | B48: 4 | C48: 120 | D48: 180 | E48: ="INSERT INTO tCR_metadata (standard_name, classification_name, acph_min, acph_max) VALUES ('"&A48&"', '"&B48&"', "&C48&", "&D48&");" -> INSERT INTO tCR_metadata (standard_name, classification_name, acph_min, acph_max) VALUES ('GERMANY VD', '4', 120, 180);
A49: GERMANY VD | B49: 3 | C49: 180 | D49: 240 | E49: ="INSERT INTO tCR_metadata (standard_name, classification_name, acph_min, acph_max) VALUES ('"&A49&"', '"&B49&"', "&C49&", "&D49&");" -> INSERT INTO tCR_metadata (standard_name, classification_name, acph_min, acph_max) VALUES ('GERMANY VD', '3', 180, 240);
A50: GERMANY VD | B50: 2 | C50: 240 | D50: 360 | E50: ="INSERT INTO tCR_metadata (standard_name, classification_name, acph_min, acph_max) VALUES ('"&A50&"', '"&B50&"', "&C50&", "&D50&");" -> INSERT INTO tCR_metadata (standard_name, classification_name, acph_min, acph_max) VALUES ('GERMANY VD', '2', 240, 360);
A51: GERMANY VD | B51: 1 | C51: 360 | D51: 550 | E51: ="INSERT INTO tCR_metadata (standard_name, classification_name, acph_min, acph_max) VALUES ('"&A51&"', '"&B51&"', "&C51&", "&D51&");" -> INSERT INTO tCR_metadata (standard_name, classification_name, acph_min, acph_max) VALUES ('GERMANY VD', '1', 360, 550);
A52: GERMANY VD | B52: 0 | C52: 400 | D52: 600 | E52: ="INSERT INTO tCR_metadata (standard_name, classification_name, acph_min, acph_max) VALUES ('"&A52&"', '"&B52&"', "&C52&", "&D52&");" -> INSERT INTO tCR_metadata (standard_name, classification_name, acph_min, acph_max) VALUES ('GERMANY VD', '0', 400, 600);
A53: AFNOR X44101 | B53: 4000000 | C53: 20 | D53: 50 | E53: ="INSERT INTO tCR_metadata (standard_name, classification_name, acph_min, acph_max) VALUES ('"&A53&"', '"&B53&"', "&C53&", "&D53&");" -> INSERT INTO tCR_metadata (standard_name, classification_name, acph_min, acph_max) VALUES ('AFNOR X44101', '4000000', 20, 50);
A54: AFNOR X44101 | B54: 400000 | C54: 60 | D54: 120 | E54: ="INSERT INTO tCR_metadata (standard_name, classification_name, acph_min, acph_max) VALUES ('"&A54&"', '"&B54&"', "&C54&", "&D54&");" -> INSERT INTO tCR_metadata (standard_name, classification_name, acph_min, acph_max) VALUES ('AFNOR X44101', '400000', 60, 120);
A55: AFNOR X44101 | B55: 4000 | C55: 120 | D55: 240 | E55: ="INSERT INTO tCR_metadata (standard_name, classification_name, acph_min, acph_max) VALUES ('"&A55&"', '"&B55&"', "&C55&", "&D55&");" -> INSERT INTO tCR_metadata (standard_name, classification_name, acph_min, acph_max) VALUES ('AFNOR X44101', '4000', 120, 240);
A56: NC-Non Classified | B56: 20µ | C56: 5 | D56: 15 | E56: ="INSERT INTO tCR_metadata (standard_name, classification_name, acph_min, acph_max) VALUES ('"&A56&"', '"&B56&"', "&C56&", "&D56&");" -> INSERT INTO tCR_metadata (standard_name, classification_name, acph_min, acph_max) VALUES ('NC-Non Classified', '20µ', 5, 15);
A57: NC-Non Classified | B57: 15µ | C57: 5 | D57: 20 | E57: ="INSERT INTO tCR_metadata (standard_name, classification_name, acph_min, acph_max) VALUES ('"&A57&"', '"&B57&"', "&C57&", "&D57&");" -> INSERT INTO tCR_metadata (standard_name, classification_name, acph_min, acph_max) VALUES ('NC-Non Classified', '15µ', 5, 20);
A58: NC-Non Classified | B58: 10µ | C58: 10 | D58: 25 | E58: ="INSERT INTO tCR_metadata (standard_name, classification_name, acph_min, acph_max) VALUES ('"&A58&"', '"&B58&"', "&C58&", "&D58&");" -> INSERT INTO tCR_metadata (standard_name, classification_name, acph_min, acph_max) VALUES ('NC-Non Classified', '10µ', 10, 25);
A59: NC-Non Classified | B59: 5µ | C59: 15 | D59: 25 | E59: ="INSERT INTO tCR_metadata (standard_name, classification_name, acph_min, acph_max) VALUES ('"&A59&"', '"&B59&"', "&C59&", "&D59&");" -> INSERT INTO tCR_metadata (standard_name, classification_name, acph_min, acph_max) VALUES ('NC-Non Classified', '5µ', 15, 25);
...

Sheet Classification
A1: ids | B1: Standards | C1: ISO_14644 | D1: FDA | E1: GMP | F1: JIS_B_9920 | G1: EUGMP | H1: WHO | I1: TGA | J1: BS_5295 | K1: GERMANY_VD | L1: AFNORX44101 | M1: NC -Non Classified
A2: =IF(B2&C3&D2="","",TRIM(TEXT(B2 & C3 & D2,0))&TEXT(ROW()-1,"00000")) -> ISO_14644ISO 8Class100K00001 | B2: ISO_14644 | C2: ISO 9 | D2: Class100K | E2: Grade D (ISO 8 at Rest & Not Defined) | F2: JIS Class 9 | G2: Grade D (ISO 7 at Rest & ISO 8 in Oper.) | H2: Asia | I2: 3500 | J2: K | M2: 20µ
A3: =IF(B3&C4&D3="","",TRIM(TEXT(B3&C4&D3,0))&TEXT(ROW()-1,"00000")) -> FDAISO 7Class10K00002 | B3: FDA | C3: ISO 8 | D3: Class10K | E3: Grade C (ISO 7 at Rest & ISO 8 in Oper.) | F3: JIS Class 8 | G3: Grade C (ISO 7 at Rest & ISO 7 in Oper.) | H3: Africa | I3: 350 | J3: J | K3: 6 | L3: 4000000 | M3: 15µ
A4: =IF(B4&C5&D4="","",TRIM(TEXT(B4&C5&D4,0))&TEXT(ROW()-1,"00000")) -> GMPISO 6Class1K00003 | B4: GMP | C4: ISO 7 | D4: Class1K | E4: Grade B (ISO 5 at Rest & ISO 7 in Oper.) | F4: JIS Class 7 | G4: Grade B (ISO 5 at Rest & ISO 7 in Oper.) | H4: North America | I4: 35 | J4: G or H | K4: 5 | L4: 400000 | M4: 10µ
A5: =IF(B5&C6&D5="","",TRIM(TEXT(B5&C6&D5,0))&TEXT(ROW()-1,"00000")) -> TGAISO 5Class 10000004 | B5: TGA | C5: ISO 6 | D5: Class 100 | E5: Grade A (ISO 5 at Rest & ISO 5 in Oper.) | F5: JIS Class 6 | G5: Grade A (ISO 5 at Rest & ISO 5 in Oper.) | H5: South America | I5: 3.5 | J5: E or F | K5: 4 | L5: - | M5: 5µ
A6: =IF(B6&C7&D6="","",TRIM(TEXT(B6&C7&D6,0))&TEXT(ROW()-1,"00000")) -> JIS_B_9920ISO 4Class 1000005 | B6: JIS_B_9920 | C6: ISO 5 | D6: Class 10 | F6: JIS Class 5 | H6: Antartica | I6: 0.35 | J6: D | K6: 3 | L6: 4000 | M6: 1µ
A7: =IF(B7&C8&D7="","",TRIM(TEXT(B7&C8&D7,0))&TEXT(ROW()-1,"00000")) -> EUGMPISO 3Class 100006 | B7: EUGMP | C7: ISO 4 | D7: Class 1 | F7: JIS Class 4 | H7: Europe | I7: 0.035 | J7: C | K7: 2 | L7: - | M7: No-Filtration
A8: =IF(B8&#REF!&D8="","",TRIM(TEXT(B8&#REF!&D8,0))&TEXT(ROW()-1,"00000")) -> #REF! | B8: WHO | C8: ISO 3 | F8: JIS Class 3 | H8: Australia | K8: 1 | L8: - | M8: Positive Pressure
A9: =IF(B9&C9&D9="","",TRIM(TEXT(B9&C9&D9,0))&TEXT(ROW()-1,"00000")) -> BS_5295ISO 200008 | B9: BS_5295 | C9: ISO 2 | F9: JIS Class 2 | K9: 0 | L9: - | M9: Exhaust
A10: =IF(B10&C10&D10="","",TRIM(TEXT(B10&C10&D10,0))&TEXT(ROW()-1,"00000")) -> GERMANY_VDISO 100009 | B10: GERMANY_VD | C10: ISO 1 | F10: JIS Class 1
A11: =IF(B11&C11&D11="","",TRIM(TEXT(B11&C11&D11,0))&TEXT(ROW()-1,"00000")) -> AFNORX4410100010 | B11: AFNORX44101
A12: =IF(B12&C12&D12="","",TRIM(TEXT(B12&C12&D12,0))&TEXT(ROW()-1,"00000")) -> NC_Non_Classified00011 | B12: NC_Non_Classified
A13: =IF(B13&C13&D13="","",TRIM(TEXT(B13&C13&D13,0))&TEXT(ROW()-1,"00000"))
A14: =IF(B14&C14&D14="","",TRIM(TEXT(B14&C14&D14,0))&TEXT(ROW()-1,"00000"))
A15: =IF(B15&C15&D15="","",TRIM(TEXT(B15&C15&D15,0))&TEXT(ROW()-1,"00000"))
A16: =IF(B16&C16&D16="","",TRIM(TEXT(B16,6))&TEXT(ROW()-1,"00000"))
A17: =IF(B17&C17&D17="","",TRIM(TEXT(B17,6))&TEXT(ROW()-1,"00000"))
A18: =IF(B18&C18&D18="","",TRIM(TEXT(B18,6))&TEXT(ROW()-1,"00000")) | E18: Filtration Stages
B19: Air-conditioning System | E19: 1S | F19: 20 micron filters made out of HDPE media with one side HDPE & other side Al. expanded mesh of efficiency 90%(150 mm thick) for fresh air supply
B20: Ventilation System | E20: 1E | F20: 20 micron filters made out of HDPE media with one side HDPE & other side Al. expanded mesh of efficiency 90%(100 mm thick) for Exhaust air.
E21: 2S | F21: 10 micron filters made out of HLP media with one side HDPE & other side Al. expanded mesh of efficiency 95%(150 mm thick) for fresh air supply
A22: TGA | B22: Adelaide | E22: 2E | F22: 10 micron filters made out of HLP media with one side HDPE & other side Al. expanded mesh of efficiency 95%(150 mm thick) for Exhaust Air
E23: 3S | F23: 5 micron filters made out of SNPF media 150GSM with one side HDPE & other side Al. expanded mesh of efficiency 99%(300 mm thick) for fresh air supply
E24: 3E | F24: 5 micron filters made out of SNPF media 150GSM with one side HDPE & other side Al. expanded mesh of efficiency 99%(300 mm thick) for Exhaust Air
E25: 4S | F25: 1 micron filters made out of SNPF media 200GSM with one side HDPE & other side Al. expanded mesh of efficiency 99.9%(300 mm thick) for fresh air supply
E26: 4E | F26: 1 micron filters made out of SNPF media 200GSM with one side HDPE & other side Al. expanded mesh of efficiency 99.9%(300 mm thick) for Exhaust Air
E27: 5S | F27: 0.3 micron 95% Eff. HEPA filters made out of imported Lydall media with efficiency 95%(300 mm thick) for fresh air supply
E28: 5E | F28: 0.3 micron 95% Eff. HEPA filters made out of imported Lydall media with efficiency 95%(300 mm thick) for Exhaust Air
E29: 6S | F29: 0.3 micron 99.97% Eff. HEPA filters made out of imported Lydall media with efficiency 95%(150 mm thick) for Supply Air
E30: 6E | F30: 0.3 micron 99.97% Eff. HEPA filters made out of imported Lydall media with efficiency 95%(150 mm thick) for Exhaust Air
E31: 7S | F31: 0.1 micron 99.9995% Eff. ULPA filters made out of imported Lydall media with efficiency 95%(150 mm thick) for Supply Air
E32: 7E | F32: 0.1 micron 99.9995% Eff. ULPA filters made out of imported Lydall media with efficiency 95%(150 mm thick) for Exhaust Air
A37: ids | B37: Standards | C37: ISO_14644 | D37: FDA | E37: GMP | F37: JIS_B_9920 | G37: EUGMP | H37: WHO | I37: TGA | J37: BS_5295 | K37: GERMANY_VD | L37: AFNORX44101 | M37: NC -Non Classified
A38: =IF(B38&C39&D38="","",TRIM(TEXT(B38 & C39 & D38,0))&TEXT(ROW()-1,"00000")) -> ISO_14644ISO 8Class100K00037 | B38: ISO_14644 | C38: ISO 9 | D38: Class100K | E38: Grade D (ISO 8 at Rest & Not Defined) | F38: JIS Class 9 | G38: Grade D (ISO 7 at Rest & ISO 8 in Oper.) | H38: Asia | I38: 3500 | J38: K | M38: 20µ
A39: =IF(B39&C40&D39="","",TRIM(TEXT(B39&C40&D39,0))&TEXT(ROW()-1,"00000")) -> FDAISO 7Class10K00038 | B39: FDA | C39: ISO 8 | D39: Class10K | E39: Grade C (ISO 7 at Rest & ISO 8 in Oper.) | F39: JIS Class 8 | G39: Grade C (ISO 7 at Rest & ISO 7 in Oper.) | H39: Africa | I39: 350 | J39: J | K39: 6 | L39: 4000000 | M39: 15µ
A40: =IF(B40&C41&D40="","",TRIM(TEXT(B40&C41&D40,0))&TEXT(ROW()-1,"00000")) -> GMPISO 6Class1K00039 | B40: GMP | C40: ISO 7 | D40: Class1K | E40: Grade B (ISO 5 at Rest & ISO 7 in Oper.) | F40: JIS Class 7 | G40: Grade B (ISO 5 at Rest & ISO 7 in Oper.) | H40: North America | I40: 35 | J40: G or H | K40: 5 | L40: 400000 | M40: 10µ
A41: =IF(B41&C42&D41="","",TRIM(TEXT(B41&C42&D41,0))&TEXT(ROW()-1,"00000")) -> TGAISO 5Class 10000040 | B41: TGA | C41: ISO 6 | D41: Class 100 | E41: Grade A (ISO 5 at Rest & ISO 5 in Oper.) | F41: JIS Class 6 | G41: Grade A (ISO 5 at Rest & ISO 5 in Oper.) | H41: South America | I41: 3.5 | J41: E or F | K41: 4 | L41: - | M41: 5µ
A42: =IF(B42&C43&D42="","",TRIM(TEXT(B42&C43&D42,0))&TEXT(ROW()-1,"00000")) -> JIS_B_9920ISO 4Class 1000041 | B42: JIS_B_9920 | C42: ISO 5 | D42: Class 10 | F42: JIS Class 5 | H42: Antartica | I42: 0.35 | J42: D | K42: 3 | L42: 4000 | M42: 1µ
A43: =IF(B43&C44&D43="","",TRIM(TEXT(B43&C44&D43,0))&TEXT(ROW()-1,"00000")) -> EUGMPISO 3Class 100042 | B43: EUGMP | C43: ISO 4 | D43: Class 1 | F43: JIS Class 4 | H43: Europe | I43: 0.035 | J43: C | K43: 2 | L43: - | M43: No-Filtration
A44: =IF(B44&#REF!&D44="","",TRIM(TEXT(B44&#REF!&D44,0))&TEXT(ROW()-1,"00000")) -> #REF! | B44: WHO | C44: ISO 3 | F44: JIS Class 3 | H44: Australia | K44: 1 | L44: - | M44: Positive Pressure
...

Sheet Input BOD
C8: ="Zoning Area AHU - " & INT((ROW()-8)/20)+1 & " " & IF(ISNUMBER(N10),"Air-Conditioning System " & IF(AH10="D","(DX)",IF(AH10="C","(Chilled Water)","")),IF(AND(N10="Amb",ISTEXT(N10)),"Ventilation System","Refer")) -> Zoning Area AHU - 1 Air-Conditioning System
C9: S.No. | D9: Room Name | E9: Length in mtrs | F9: Width in mtrs | G9: Height in mtrs | H9: People in Nos | I9: Eqpt. Load in KW | J9: Lighting in W/Sft | K9: No.of Inf./Hr | L9: Fresh Air | M9: Exhaust | N9: T ˚C (Required inside) | O9: RH(in) +/- 5% | P9: Peak Max Temp.(Out) in ˚C | Q9: RH(Out) in +/- 5% | R9: Select Class | S9: ACPH | T9: Chilled water enter C Direct Expansion enter D | U9: Select Standards | V9: Manual Entry for ACPH
C10: 1 | D10: Chandrashekar | E10: 1 | F10: 1 | G10: 2 | H10: 1 | I10: 2 | J10: 1.75 | K10: 2 | L10: 0.1 | M10: 0 | N10: 24 | O10: 50 | P10: 41 | Q10: 85 | R10: Class100K | S10: =Y10 -> 12 | T10: D | U10: FDA | V10: 0 | Y10: =IF(AND(ISNUMBER(V10), V10>0), V10, IFERROR(INDEX('Class Air Changes'!$E$6:$E$75, MATCH(R10, 'Class Air Changes'!$D$6:$D$75, 0)), "Not Found")) -> 12
C11: 2 | D11: vijay bhasker | E11: 1 | F11: 1 | G11: 2 | H11: 1 | I11: 2 | J11: 1.75 | K11: 2 | L11: 0.1 | M11: 0 | N11: =N10 -> 24 | O11: 50 | P11: =P10 -> 41 | Q11: 85 | R11: =R10 -> Class100K | S11: =S10 -> 12 | T11: D | U11: =U10 -> FDA | V11: =V10 -> 0 | Y11: =IF(AND(ISNUMBER(X11), X11>0), X11, IFERROR(INDEX('Class Air Changes'!$E$6:$E$75, MATCH(R11, 'Class Air Changes'!$D$6:$D$75, 0)), "Not Found")) -> 12
C12: 3 | D12: nimma | E12: 1 | F12: 1 | G12: 2 | H12: 1 | I12: 2 | J12: 1.75 | K12: 2 | L12: 0.1 | M12: 0 | N12: =N11 -> 24 | O12: 50 | P12: =P11 -> 41 | Q12: 85 | R12: =R11 -> Class100K | S12: =S11 -> 12 | T12: D | U12: =U11 -> FDA | V12: =V11 -> 0 | Y12: =IF(AND(ISNUMBER(X12), X12>0), X12, IFERROR(INDEX('Class Air Changes'!$E$6:$E$75, MATCH(R12, 'Class Air Changes'!$D$6:$D$75, 0)), "Not Found")) -> 12
C13: 4 | D13: sahajanand | E13: 1 | F13: 1 | G13: 2 | H13: 1 | I13: 2 | J13: 1.75 | K13: 2 | L13: 0.1 | M13: 0 | N13: =N12 -> 24 | O13: 50 | P13: =P12 -> 41 | Q13: 85 | R13: =R12 -> Class100K | S13: =S12 -> 12 | T13: D | U13: =U12 -> FDA | V13: =V12 -> 0 | Y13: =IF(AND(ISNUMBER(X13), X13>0), X13, IFERROR(INDEX('Class Air Changes'!$E$6:$E$75, MATCH(R13, 'Class Air Changes'!$D$6:$D$75, 0)), "Not Found")) -> 12
C14: 5 | D14: xyz | E14: 1 | F14: 1 | G14: 2 | H14: 1 | I14: 2 | J14: 1.75 | K14: 2 | L14: 0.1 | M14: 0 | N14: =N13 -> 24 | O14: 50 | P14: =P13 -> 41 | Q14: 85 | R14: =R13 -> Class100K | S14: =S13 -> 12 | T14: D | U14: =U13 -> FDA | V14: =V13 -> 0 | Y14: =IF(AND(ISNUMBER(X14), X14>0), X14, IFERROR(INDEX('Class Air Changes'!$E$6:$E$75, MATCH(R14, 'Class Air Changes'!$D$6:$D$75, 0)), "Not Found")) -> 12
C15: 6 | D15: abc | E15: 1 | F15: 1 | G15: 2 | H15: 1 | I15: 2 | J15: 1.75 | K15: 2 | L15: 0.1 | M15: 0 | N15: =N14 -> 24 | O15: 50 | P15: =P14 -> 41 | Q15: 85 | R15: =R14 -> Class100K | S15: =S14 -> 12 | T15: D | U15: =U14 -> FDA | V15: =V14 -> 0 | Y15: =IF(AND(ISNUMBER(X15), X15>0), X15, IFERROR(INDEX('Class Air Changes'!$E$6:$E$75, MATCH(R15, 'Class Air Changes'!$D$6:$D$75, 0)), "Not Found")) -> 12
C16: 7 | D16: excel | E16: 1 | F16: 1 | G16: 2 | H16: 1 | I16: 2 | J16: 1.75 | K16: 2 | L16: 0.1 | M16: 0 | N16: =N15 -> 24 | O16: 50 | P16: =P15 -> 41 | Q16: 85 | R16: =R15 -> Class100K | S16: =S15 -> 12 | T16: D | U16: =U15 -> FDA | V16: =V15 -> 0 | Y16: =IF(AND(ISNUMBER(X16), X16>0), X16, IFERROR(INDEX('Class Air Changes'!$E$6:$E$75, MATCH(R16, 'Class Air Changes'!$D$6:$D$75, 0)), "Not Found")) -> 12
C17: 8 | D17: word | E17: 1 | F17: 1 | G17: 2 | H17: 1 | I17: 2 | J17: 1.75 | K17: 2 | L17: 0.1 | M17: 0 | N17: =N16 -> 24 | O17: 50 | P17: =P16 -> 41 | Q17: 85 | R17: =R16 -> Class100K | S17: =S16 -> 12 | T17: D | U17: =U16 -> FDA | V17: =V16 -> 0 | Y17: =IF(AND(ISNUMBER(X17), X17>0), X17, IFERROR(INDEX('Class Air Changes'!$E$6:$E$75, MATCH(R17, 'Class Air Changes'!$D$6:$D$75, 0)), "Not Found")) -> 12
C18: 9 | D18: java | E18: 1 | F18: 1 | G18: 2 | H18: 1 | I18: 2 | J18: 1.75 | K18: 2 | L18: 0.1 | M18: 0 | N18: =N17 -> 24 | O18: 50 | P18: =P17 -> 41 | Q18: 85 | R18: =R17 -> Class100K | S18: =S17 -> 12 | T18: D | U18: =U17 -> FDA | V18: =V17 -> 0 | Y18: =IF(AND(ISNUMBER(X18), X18>0), X18, IFERROR(INDEX('Class Air Changes'!$E$6:$E$75, MATCH(R18, 'Class Air Changes'!$D$6:$D$75, 0)), "Not Found")) -> 12
C19: 10 | D19: 12345 | E19: 1 | F19: 1 | G19: 2 | H19: 1 | I19: 2 | J19: 1.75 | K19: 2 | L19: 0.1 | M19: 0 | N19: =N18 -> 24 | O19: 50 | P19: =P18 -> 41 | Q19: 85 | R19: =R18 -> Class100K | S19: =S18 -> 12 | T19: D | U19: =U18 -> FDA | V19: =V18 -> 0 | Y19: =IF(AND(ISNUMBER(X19), X19>0), X19, IFERROR(INDEX('Class Air Changes'!$E$6:$E$75, MATCH(R19, 'Class Air Changes'!$D$6:$D$75, 0)), "Not Found")) -> 12
C20: 11 | D20: cvdwvjvq | E20: 1 | F20: 1 | G20: 2 | H20: 1 | I20: 2 | J20: 1.75 | K20: 2 | L20: 0.1 | M20: 0 | N20: =N19 -> 24 | O20: 50 | P20: =P19 -> 41 | Q20: 85 | R20: =R19 -> Class100K | S20: =S19 -> 12 | T20: D | U20: =U19 -> FDA | V20: =V19 -> 0 | Y20: =IF(AND(ISNUMBER(X20), X20>0), X20, IFERROR(INDEX('Class Air Changes'!$E$6:$E$75, MATCH(R20, 'Class Air Changes'!$D$6:$D$75, 0)), "Not Found")) -> 12
C21: 12 | D21: jcvbbvk | E21: 1 | F21: 1 | G21: 2 | H21: 1 | I21: 2 | J21: 1.75 | K21: 2 | L21: 0.1 | M21: 0 | N21: =N20 -> 24 | O21: 50 | P21: =P20 -> 41 | Q21: 85 | R21: =R20 -> Class100K | S21: =S20 -> 12 | T21: D | U21: =U20 -> FDA | V21: =V20 -> 0 | Y21: =IF(AND(ISNUMBER(X21), X21>0), X21, IFERROR(INDEX('Class Air Changes'!$E$6:$E$75, MATCH(R21, 'Class Air Changes'!$D$6:$D$75, 0)), "Not Found")) -> 12
C22: 13 | D22: vbwbvb | E22: 1 | F22: 1 | G22: 2 | H22: 1 | I22: 2 | J22: 1.75 | K22: 2 | L22: 0.1 | M22: 0 | N22: =N21 -> 24 | O22: 50 | P22: =P21 -> 41 | Q22: 85 | R22: =R21 -> Class100K | S22: =S21 -> 12 | T22: D | U22: =U21 -> FDA | V22: =V21 -> 0 | Y22: =IF(AND(ISNUMBER(X22), X22>0), X22, IFERROR(INDEX('Class Air Changes'!$E$6:$E$75, MATCH(R22, 'Class Air Changes'!$D$6:$D$75, 0)), "Not Found")) -> 12
C23: 14 | D23: b cjvjvve | E23: 1 | F23: 1 | G23: 2 | H23: 1 | I23: 2 | J23: 1.75 | K23: 2 | L23: 0.1 | M23: 0 | N23: =N22 -> 24 | O23: 50 | P23: =P22 -> 41 | Q23: 85 | R23: =R22 -> Class100K | S23: =S22 -> 12 | T23: D | U23: =U22 -> FDA | V23: =V22 -> 0 | Y23: =IF(AND(ISNUMBER(X23), X23>0), X23, IFERROR(INDEX('Class Air Changes'!$E$6:$E$75, MATCH(R23, 'Class Air Changes'!$D$6:$D$75, 0)), "Not Found")) -> 12
C24: 15 | D24: ifhiuhfigi | E24: 1 | F24: 1 | G24: 2 | H24: 1 | I24: 2 | J24: 1.75 | K24: 2 | L24: 0.1 | M24: 0 | N24: =N23 -> 24 | O24: 50 | P24: =P23 -> 41 | Q24: 85 | R24: =R23 -> Class100K | S24: =S23 -> 12 | T24: D | U24: =U23 -> FDA | V24: =V23 -> 0 | Y24: =IF(AND(ISNUMBER(X24), X24>0), X24, IFERROR(INDEX('Class Air Changes'!$E$6:$E$75, MATCH(R24, 'Class Air Changes'!$D$6:$D$75, 0)), "Not Found")) -> 12
C25: 16 | D25: hbhwbfb | E25: 1 | F25: 1 | G25: 2 | H25: 1 | I25: 2 | J25: 1.75 | K25: 2 | L25: 0.1 | M25: 0 | N25: =N24 -> 24 | O25: 50 | P25: =P24 -> 41 | Q25: 85 | R25: =R24 -> Class100K | S25: =S24 -> 12 | T25: D | U25: =U24 -> FDA | V25: =V24 -> 0 | Y25: =IF(AND(ISNUMBER(X25), X25>0), X25, IFERROR(INDEX('Class Air Changes'!$E$6:$E$75, MATCH(R25, 'Class Air Changes'!$D$6:$D$75, 0)), "Not Found")) -> 12
C26: =IF(D26<>"",COUNTA($D$10:D26),"")
C27: =IF(D27<>"",COUNTA($D$10:D27),"")
C28: ="Zoning Area AHU - " & INT((ROW()-8)/20)+1 & " " & IF(ISNUMBER(N30),"Air-Conditioning System " & IF(AH30="D","(DX)",IF(AH30="C","(Chilled Water)","")),IF(AND(N30="Amb",ISTEXT(N30)),"Ventilation System","Refer")) -> Zoning Area AHU - 2 Air-Conditioning System
D29: Room Name | E29: Length in mtrs | F29: Width in mtrs | G29: Height in mtrs | H29: People in Nos | I29: Eqpt. Load in KW | J29: Lighting in W/Sft | K29: No.of Inf./Hr | L29: Fresh Air | M29: Exhaust | N29: T ˚C (Required inside) | O29: RH(in) +/- 5% | P29: Peak Max Temp.(Out) in ˚C | Q29: RH(Out) in +/- 5% | R29: Class | S29: ACPH | T29: ACPH
C30: =IF(D30<>"",COUNTA($D$10:D30),"") -> 18 | D30: Clean Room 10 | E30: 3 | F30: 3 | G30: 2.4 | H30: 1 | I30: 2 | J30: 1.75 | K30: 3 | L30: 0.1 | M30: 0 | N30: 24 | O30: 50 | P30: 45 | Q30: 85 | R30: ISO 6 | S30: 160 | T30: C
C31: =IF(D31<>"",COUNTA($D$10:D31),"") -> 19 | D31: Clean Room 11 | E31: 1.8 | F31: 2.2 | G31: 2.4 | H31: 2 | I31: 1 | J31: 1.75 | K31: 3 | L31: 0.1 | M31: 0 | N31: 24 | O31: 50 | P31: 45 | Q31: 85 | R31: ISO 6 | S31: 160 | T31: C
C32: =IF(D32<>"",COUNTA($D$10:D32),"") -> 20 | D32: Clean Room 12 | E32: 1.5 | F32: 2.8 | G32: 2.4 | H32: 2 | I32: 3 | J32: 1.75 | K32: 3 | L32: 0.1 | M32: 0 | N32: 24 | O32: 50 | P32: 45 | Q32: 85 | R32: ISO 6 | S32: 160 | T32: C
C33: =IF(D33<>"",COUNTA($D$10:D33),"") -> 21 | D33: Clean Room 13 | E33: 2.1 | F33: 3.5 | G33: 2.4 | H33: 0 | I33: 1 | J33: 1.75 | K33: 3 | L33: 0.1 | M33: 0 | N33: 24 | O33: 50 | P33: 45 | Q33: 85 | R33: ISO 6 | S33: 160 | T33: C
C34: =IF(D34<>"",COUNTA($D$10:D34),"") -> 22 | D34: Clean Room 14 | E34: 2.7 | F34: 4 | G34: 2.4 | H34: 2 | I34: 1 | J34: 1.75 | K34: 3 | L34: 0.1 | M34: 0 | N34: 24 | O34: 50 | P34: 45 | Q34: 85 | R34: ISO 6 | S34: 160 | T34: C
C35: =IF(D35<>"",COUNTA($D$10:D35),"") -> 23 | D35: Clean Room 15 | E35: 3.8 | F35: 4.2 | G35: 2.4 | H35: 3 | I35: 3 | J35: 1.75 | K35: 3 | L35: 0.1 | M35: 0 | N35: 24 | O35: 50 | P35: 45 | Q35: 85 | R35: ISO 6 | S35: 160 | T35: C
C36: =IF(D36<>"",COUNTA($D$10:D36),"") -> 24 | D36: Clean Room 16 | E36: 3.1 | F36: 2.6 | G36: 2.4 | H36: 2 | I36: 1 | J36: 1.75 | K36: 3 | L36: 0.1 | M36: 0 | N36: 24 | O36: 50 | P36: 45 | Q36: 85 | R36: ISO 6 | S36: 160 | T36: C
C37: =IF(D37<>"",COUNTA($D$10:D37),"") -> 25 | D37: Clean Room 17 | E37: 1.9 | F37: 2.4 | G37: 2.4 | H37: 3 | I37: 2 | J37: 1.75 | K37: 3 | L37: 0.1 | M37: 0 | N37: 24 | O37: 50 | P37: 45 | Q37: 85 | R37: ISO 6 | S37: 160 | T37: C
C38: =IF(D38<>"",COUNTA($D$10:D38),"") -> 26 | D38: Clean Room 18 | E38: 3 | F38: 2.9 | G38: 2.4 | H38: 2 | I38: 1 | J38: 1.75 | K38: 3 | L38: 0.1 | M38: 0 | N38: 24 | O38: 50 | P38: 45 | Q38: 85 | R38: ISO 6 | S38: 160 | T38: C
C39: =IF(D39<>"",COUNTA($D$10:D39),"") -> 27 | D39: Clean Room 19 | E39: 2.4 | F39: 2 | G39: 2.4 | H39: 2 | I39: 1 | J39: 1.75 | K39: 3 | L39: 0.1 | M39: 0 | N39: 24 | O39: 50 | P39: 45 | Q39: 85 | R39: ISO 6 | S39: 160 | T39: C
C40: =IF(D40<>"",COUNTA($D$10:D40),"") -> 28 | D40: Clean Room 20 | E40: 2.1 | F40: 1.8 | G40: 2.4 | H40: 2 | I40: 1 | J40: 1.75 | K40: 3 | L40: 0.1 | M40: 0 | N40: 24 | O40: 50 | P40: 45 | Q40: 85 | R40: ISO 6 | S40: 160 | T40: C
C41: =IF(D41<>"",COUNTA($D$10:D41),"") -> 29 | D41: Clean Room 21 | E41: 1.8 | F41: 1.9 | G41: 2.4 | H41: 2 | I41: 1 | J41: 1.75 | K41: 3 | L41: 0.1 | M41: 0 | N41: 24 | O41: 50 | P41: 45 | Q41: 85 | R41: ISO 6 | S41: 160 | T41: C
... C45: =IF(D45<>"",COUNTA($D$10:D45),"") -> 33 | D45: Clean Room 25 | E45: 2.8 | F45: 2.4 | G45: 2.4 | H45: 2 | I45: 1 | J45: 1.75 | K45: 3 | L45: 0.1 | M45: 0 | N45: 24 | O45: 50 | P45: 45 | Q45: 85 | R45: ISO 6 | S45: 160 | T45: C
C46: =IF(D46<>"",COUNTA($D$10:D46),"")
C47: =IF(D47<>"",COUNTA($D$10:D47),"")
C48: ="Zoning Area AHU - " & INT((ROW()-8)/20)+1 & " " & IF(ISNUMBER(N50),"Air-Conditioning System " & IF(AH50="D","(DX)",IF(AH50="C","(Chilled Water)","")),IF(AND(N50="Amb",ISTEXT(N50)),"Ventilation System","Refer")) -> Zoning Area AHU - 3 Air-Conditioning System
C49: =IF(D49<>"",COUNTA($D$10:D49),"") -> 34 | D49: Room Name | E49: Length in mtrs | F49: Width in mtrs | G49: Height in mtrs | H49: People in Nos | I49: Eqpt. Load in KW | J49: Lighting in W/Sft | K49: No.of Inf./Hr | L49: Fresh Air | M49: Exhaust | N49: T ˚C (Required inside) | O49: RH(in) +/- 5% | P49: Peak Max Temp.(Out) in ˚C | Q49: RH(Out) in +/- 5% | R49: Class | S49: ACPH | T49: ACPH
C50: =IF(D50<>"",COUNTA($D$10:D50),"") -> 35 | D50: Clean Room 10 | E50: 3 | F50: 3 | G50: 2.4 | H50: 1 | I50: 2 | J50: 1.75 | K50: 3 | L50: 0.1 | M50: 0 | N50: 24 | O50: 50 | P50: 45 | Q50: 85 | R50: GRADE A | S50: 150 | T50: C
...

Sheet Output BOD
C8: ="Zoning Area AHU - " & INT((ROW()-8)/20)+1 & " " &IF(AQ10>0,"Air-Conditioning System " & IF(AH10="D","(DX)",IF(AH10="C","(Chilled Water)","")),IF(AND(N10="Amb",AQ10=0),"Ventilation System","Refer")) -> Zoning Area AHU - 1 Air-Conditioning System (DX) | AS8: Chilled Water Details | AW8: Hot Water/Steam Details
C9: S.No. | D9: Room Name | E9: Length in mtrs | F9: Width in mtrs | G9: Height in mtrs | H9: People in Nos | I9: Eqpt. Load in KW | J9: Lighting in W/Sft | K9: No.of Inf./Hr | L9: Fresh Air | M9: Exhaust | N9: T ˚C (Required inside) | O9: RH(in) +/- 5% | P9: Peak Max Temp.(Out) in ˚C | Q9: RH(Out) in +/- 5% | R9: Class | S9: ACPH | T9: Peak Min Temp.(Out) in ˚C | U9: RH(Out) +/- 5% | V9: Class | W9: ACPH | X9: Area | Y9: Volume | Z9: Room Cfm | AA9: FA | AB9: EA | AC9: Rem. Water vapour Kg/hr | AD9: Deh. Cfm | AE9: Res. Cfm | AF9: Room Terminal Supply Module in Sft | AG9: Res. Cooling Load in TR | AH9: Chilled Water (C) OR DX (D) | AI9: Room AC load in TR | AJ9: Cfm AC load in TR | AK9: AHU Cfm | AL9: AHU Size | AM9: Static Pressure | AN9: Blower Model BDB | AO9: Motor Selected in Hp | AP9: No. of Rows of Cooling Coil | AQ9: AHU Cooling Load in TR | AR9: No. Of Stages of Filtr. | AS9: Chilled water in GPM | AT9: Chilled water in L/s | AU9: Flow Velocity in m/s | AV9: Pipe Size in mm | AW9: Hot Water/Steam in GPM | AX9: Hot water/Steam in L/s | AY9: Flow Velocity | AZ9: Pipe Size
C10: ='Input BOD'!C10 -> 1 | D10: ='BOD-Cold & Amb.'!D10 -> Chandrashekar | E10: ='BOD-Cold & Amb.'!E10 -> 1 | F10: ='BOD-Cold & Amb.'!F10 -> 1 | G10: ='BOD-Cold & Amb.'!G10 -> 2 | H10: ='BOD-Cold & Amb.'!H10 -> 1 | I10: ='BOD-Cold & Amb.'!I10 -> 2 | J10: ='BOD-Cold & Amb.'!J10 -> 1.75 | K10: ='BOD-Cold & Amb.'!K10 -> 2 | ... AJ10: ='BOD-Cold & Amb.'!AJ10 -> 3.5 | AK10: ='BOD-Cold & Amb.'!AK10:AK25 -> 15750 | AL10: W | AM10: ='BOD-Cold & Amb.'!AM10:AM25 -> 125 | AN10: ='BOD-Cold & Amb.'!AN10:AN25 -> 710 | AO10: ='BOD-Cold & Amb.'!AO10:AO25 -> 20 | AP10: ='BOD-Cold & Amb.'!AP10:AP25 -> 8 | AQ10: ='BOD-Cold & Amb.'!AQ10:AQ25 -> 56 | AR10: ='BOD-Cold & Amb.'!AR10:AR25 -> 3 | AS10: ='BOD-Cold & Amb.'!AS10:AS25 -> 224 | AT10: ='BOD-Cold & Amb.'!AT10:AT25 -> 14.13216 | ... AV10: ='BOD-Cold & Amb.'!AV10:AV25 -> 94.875581
C11: ='Input BOD'!C11 -> 2 | D11: ='BOD-Cold & Amb.'!D11 -> vijay bhasker | E11: ='BOD-Cold & Amb.'!E11 -> 1 | F11: ='BOD-Cold & Amb.'!F11 -> 1 | G11: ='BOD-Cold & Amb.'!G11 -> 2 | H11: ='BOD-Cold & Amb.'!H11 -> 1 | I11: ='BOD-Cold & Amb.'!I11 -> 2 | J11: ='BOD-Cold & Amb.'!J11 -> 1.75 | K11: ='BOD-Cold & Amb.'!K11 -> 2 | ... AJ11: ='BOD-Cold & Amb.'!AJ11 -> 3.5 | AL11: ='BOD-Cold & Amb.'!AL11 -> 2050
C12: ='Input BOD'!C12 -> 3 | D12: ='BOD-Cold & Amb.'!D12 -> nimma | E12: ='BOD-Cold & Amb.'!E12 -> 1 | F12: ='BOD-Cold & Amb.'!F12 -> 1 | G12: ='BOD-Cold & Amb.'!G12 -> 2 | H12: ='BOD-Cold & Amb.'!H12 -> 1 | I12: ='BOD-Cold & Amb.'!I12 -> 2 | J12: ='BOD-Cold & Amb.'!J12 -> 1.75 | K12: ='BOD-Cold & Amb.'!K12 -> 2 | ... AJ12: ='BOD-Cold & Amb.'!AJ12 -> 3.5 | AL12: H
C13: ='Input BOD'!C13 -> 4 | D13: ='BOD-Cold & Amb.'!D13 -> sahajanand | E13: ='BOD-Cold & Amb.'!E13 -> 1 | F13: ='BOD-Cold & Amb.'!F13 -> 1 | G13: ='BOD-Cold & Amb.'!G13 -> 2 | H13: ='BOD-Cold & Amb.'!H13 -> 1 | I13: ='BOD-Cold & Amb.'!I13 -> 2 | J13: ='BOD-Cold & Amb.'!J13 -> 1.75 | K13: ='BOD-Cold & Amb.'!K13 -> 2 | ... AJ13: ='BOD-Cold & Amb.'!AJ13 -> 3.5 | AL13: ='BOD-Cold & Amb.'!AL13 -> 2050
C14: ='Input BOD'!C14 -> 5 | D14: ='BOD-Cold & Amb.'!D14 -> xyz | E14: ='BOD-Cold & Amb.'!E14 -> 1 | F14: ='BOD-Cold & Amb.'!F14 -> 1 | G14: ='BOD-Cold & Amb.'!G14 -> 2 | H14: ='BOD-Cold & Amb.'!H14 -> 1 | I14: ='BOD-Cold & Amb.'!I14 -> 2 | J14: ='BOD-Cold & Amb.'!J14 -> 1.75 | K14: ='BOD-Cold & Amb.'!K14 -> 2 | ... AJ14: ='BOD-Cold & Amb.'!AJ14 -> 3.5 | AL14: L
C15: ='Input BOD'!C15 -> 6 | D15: ='BOD-Cold & Amb.'!D15 -> abc | E15: ='BOD-Cold & Amb.'!E15 -> 1 | F15: ='BOD-Cold & Amb.'!F15 -> 1 | G15: ='BOD-Cold & Amb.'!G15 -> 2 | H15: ='BOD-Cold & Amb.'!H15 -> 1 | I15: ='BOD-Cold & Amb.'!I15 -> 2 | J15: ='BOD-Cold & Amb.'!J15 -> 1.75 | K15: ='BOD-Cold & Amb.'!K15 -> 2 | ... AJ15: ='BOD-Cold & Amb.'!AJ15 -> 3.5 | AL15: ='BOD-Cold & Amb.'!AL15 -> 5900
C16: ='Input BOD'!C16 -> 7 | D16: ='BOD-Cold & Amb.'!D16 -> excel | E16: ='BOD-Cold & Amb.'!E16 -> 1 | F16: ='BOD-Cold & Amb.'!F16 -> 1 | G16: ='BOD-Cold & Amb.'!G16 -> 2 | H16: ='BOD-Cold & Amb.'!H16 -> 1 | I16: ='BOD-Cold & Amb.'!I16 -> 2 | J16: ='BOD-Cold & Amb.'!J16 -> 1.75 | K16: ='BOD-Cold & Amb.'!K16 -> 2 | ... AJ16: ='BOD-Cold & Amb.'!AJ16 -> 3.5
C17: ='Input BOD'!C17 -> 8 | D17: ='BOD-Cold & Amb.'!D17 -> word | E17: ='BOD-Cold & Amb.'!E17 -> 1 | F17: ='BOD-Cold & Amb.'!F17 -> 1 | G17: ='BOD-Cold & Amb.'!G17 -> 2 | H17: ='BOD-Cold & Amb.'!H17 -> 1 | I17: ='BOD-Cold & Amb.'!I17 -> 2 | J17: ='BOD-Cold & Amb.'!J17 -> 1.75 | K17: ='BOD-Cold & Amb.'!K17 -> 2 | ... AJ17: ='BOD-Cold & Amb.'!AJ17 -> 3.5
C18: ='Input BOD'!C18 -> 9 | D18: ='BOD-Cold & Amb.'!D18 -> java | E18: ='BOD-Cold & Amb.'!E18 -> 1 | F18: ='BOD-Cold & Amb.'!F18 -> 1 | G18: ='BOD-Cold & Amb.'!G18 -> 2 | H18: ='BOD-Cold & Amb.'!H18 -> 1 | I18: ='BOD-Cold & Amb.'!I18 -> 2 | J18: ='BOD-Cold & Amb.'!J18 -> 1.75 | K18: ='BOD-Cold & Amb.'!K18 -> 2 | ... AJ18: ='BOD-Cold & Amb.'!AJ18 -> 3.5
C19: ='Input BOD'!C19 -> 10 | D19: ='BOD-Cold & Amb.'!D19 -> 12345 | E19: ='BOD-Cold & Amb.'!E19 -> 1 | F19: ='BOD-Cold & Amb.'!F19 -> 1 | G19: ='BOD-Cold & Amb.'!G19 -> 2 | H19: ='BOD-Cold & Amb.'!H19 -> 1 | I19: ='BOD-Cold & Amb.'!I19 -> 2 | J19: ='BOD-Cold & Amb.'!J19 -> 1.75 | K19: ='BOD-Cold & Amb.'!K19 -> 2 | ... AJ19: ='BOD-Cold & Amb.'!AJ19 -> 3.5 | AL19: ='BOD-Cold & Amb.'!AL19 -> 5500
C20: ='Input BOD'!C20 -> 11 | D20: ='BOD-Cold & Amb.'!D20 -> cvdwvjvq | E20: ='BOD-Cold & Amb.'!E20 -> 1 | F20: ='BOD-Cold & Amb.'!F20 -> 1 | G20: ='BOD-Cold & Amb.'!G20 -> 2 | H20: ='BOD-Cold & Amb.'!H20 -> 1 | I20: ='BOD-Cold & Amb.'!I20 -> 2 | J20: ='BOD-Cold & Amb.'!J20 -> 1.75 | K20: ='BOD-Cold & Amb.'!K20 -> 2 | ... AJ20: ='BOD-Cold & Amb.'!AJ20 -> 3.5
C21: ='Input BOD'!C21 -> 12 | D21: ='BOD-Cold & Amb.'!D21 -> jcvbbvk | E21: ='BOD-Cold & Amb.'!E21 -> 1 | F21: ='BOD-Cold & Amb.'!F21 -> 1 | G21: ='BOD-Cold & Amb.'!G21 -> 2 | H21: ='BOD-Cold & Amb.'!H21 -> 1 | I21: ='BOD-Cold & Amb.'!I21 -> 2 | J21: ='BOD-Cold & Amb.'!J21 -> 1.75 | K21: ='BOD-Cold & Amb.'!K21 -> 2 | ... AJ21: ='BOD-Cold & Amb.'!AJ21 -> 3.5
C22: ='Input BOD'!C22 -> 13 | D22: ='BOD-Cold & Amb.'!D22 -> vbwbvb | E22: ='BOD-Cold & Amb.'!E22 -> 1 | F22: ='BOD-Cold & Amb.'!F22 -> 1 | G22: ='BOD-Cold & Amb.'!G22 -> 2 | H22: ='BOD-Cold & Amb.'!H22 -> 1 | I22: ='BOD-Cold & Amb.'!I22 -> 2 | J22: ='BOD-Cold & Amb.'!J22 -> 1.75 | K22: ='BOD-Cold & Amb.'!K22 -> 2 | ... AJ22: ='BOD-Cold & Amb.'!AJ22 -> 3.5
C23: ='Input BOD'!C23 -> 14 | D23: ='BOD-Cold & Amb.'!D23 -> b cjvjvve | E23: ='BOD-Cold & Amb.'!E23 -> 1 | F23: ='BOD-Cold & Amb.'!F23 -> 1 | G23: ='BOD-Cold & Amb.'!G23 -> 2 | H23: ='BOD-Cold & Amb.'!H23 -> 1 | I23: ='BOD-Cold & Amb.'!I23 -> 2 | J23: ='BOD-Cold & Amb.'!J23 -> 1.75 | K23: ='BOD-Cold & Amb.'!K23 -> 2 | ... AJ23: ='BOD-Cold & Amb.'!AJ23 -> 3.5
C24: ='Input BOD'!C24 -> 15 | D24: ='BOD-Cold & Amb.'!D24 -> ifhiuhfigi | E24: ='BOD-Cold & Amb.'!E24 -> 1 | F24: ='BOD-Cold & Amb.'!F24 -> 1 | G24: ='BOD-Cold & Amb.'!G24 -> 2 | H24: ='BOD-Cold & Amb.'!H24 -> 1 | I24: ='BOD-Cold & Amb.'!I24 -> 2 | J24: ='BOD-Cold & Amb.'!J24 -> 1.75 | K24: ='BOD-Cold & Amb.'!K24 -> 2 | ... AJ24: ='BOD-Cold & Amb.'!AJ24 -> 3.5
C25: ='Input BOD'!C25 -> 16 | D25: ='BOD-Cold & Amb.'!D25 -> hbhwbfb | E25: ='BOD-Cold & Amb.'!E25 -> 1 | F25: ='BOD-Cold & Amb.'!F25 -> 1 | G25: ='BOD-Cold & Amb.'!G25 -> 2 | H25: ='BOD-Cold & Amb.'!H25 -> 1 | I25: ='BOD-Cold & Amb.'!I25 -> 2 | J25: ='BOD-Cold & Amb.'!J25 -> 1.75 | K25: ='BOD-Cold & Amb.'!K25 -> 2 | ... AJ25: ='BOD-Cold & Amb.'!AJ25 -> 3.5
C26: =IF(D26<>"",COUNTA($D$10:D26),"") | X26: =SUM(X10:X25) -> 172.16 | Y26: =SUM(Y10:Y25) -> 1129.3696 | Z26: =SUM(Z10:Z25) -> 225.87392 | AA26: =SUM(AA10:AA25) -> 22.587392 | AB26: =SUM(AB10:AB25) -> 0 | AC26: =SUM(AC10:AC25) -> 1.5729225 | AD26: =SUM(AD10:AD25) -> 15600 | AE26: =SUM(AE10:AE25) -> 15600 | ... AG26: =SUM(AG10:AG25) -> 56 | AI26: =SUM(AI10:AI25) -> 40 | AJ26: =SUM(AJ10:AJ25) -> 56
C27: =IF(D27<>"",COUNTA($D$10:D27),"")
C28: ="Zoning Area AHU - " & INT((ROW()-8)/20)+1 & " " &IF(AQ30>0,"Air-Conditioning System " & IF(AH30="D","(DX)",IF(AH30="C","(Chilled Water)","")),IF(AND(N30="Amb",AQ30=0),"Ventilation System","Refer")) -> #DIV/0! | AS28: Chilled Water Details | AW28: Hot Water/Steam Details
D29: Room Name | E29: Length in mtrs | F29: Width in mtrs | G29: Height in mtrs | H29: People in Nos | I29: Eqpt. Load in KW | J29: Lighting in W/Sft | K29: No.of Inf./Hr | L29: Fresh Air | M29: Exhaust | N29: T ˚C (Required inside) | O29: RH(in) +/- 5% | P29: Peak Max Temp.(Out) in ˚C | Q29: RH(Out) in +/- 5% | R29: Class | S29: ACPH | T29: Peak Min Temp.(Out) in ˚C | U29: RH(Out) +/- 5% | V29: Class | W29: ACPH | X29: Area | Y29: Volume | Z29: Room Cfm | AA29: FA | AB29: EA | AC29: Rem. Water vapour Kg/hr | AD29: Deh. Cfm | AE29: Res. Cfm | AF29: Room Terminal Supply Module in Sft | AG29: Res. Cooling Load in TR | AH29: Chilled Water (C) OR DX (D) | AI29: Room AC load in TR | AJ29: Cfm AC load in TR | AK29: AHU Cfm | AL29: AHU Size | AM29: Static Pressure | AN29: Blower Model BDB | AO29: Motor Selected in Hp | AP29: No. of Rows of Cooling Coil | AQ29: AHU Cooling Load in TR | AR29: No. Of Stages of Filtr. | AS29: Chilled water in GPM | AT29: Chilled water in L/s | AU29: Flow Velocity in m/s | AV29: Pipe Size in mm | AW29: Hot Water/Steam in GPM | AX29: Hot water/Steam in L/s | AY29: Flow Velocity | AZ29: Pipe Size
C30: =IF(D30<>"",COUNTA($D$10:D30),"") -> 18 | D30: Clean Room 10 | E30: 3 | F30: 3 | G30: 2.4 | H30: 1 | I30: 2 | J30: 1.75 | K30: 3 | L30: 0.1 | M30: 0 | N30: 24 | O30: 50 | P30: 45 | Q30: 85 | R30: ISO 6 | S30: 160 | T30: 0 | U30: 100 | V30: =R30 -> ISO 6 | W30: =S30 -> 160 | X30: =E30*F30*10.76 -> 96.84 | Y30: =X30*G30*3.28 -> 762.32448 | Z30: =Y30*S30/60 -> 2032.8653 | AA30: =Z30*L30 -> 203.28653 | AB30: =IF(N30="Amb",Z30,Z30*M30) -> 0 | AC30: =IF(ISNUMBER(N30), (AA30*0.075*60/2.20462)*BP30/7000, "Ambient") -> 0 | AD30: =IF(ISNUMBER(N30), CEILING(CF30/(0.68*BP30),25), "Ambient") -> #DIV/0! | AE30: =CEILING(MAX((Z30+AA30),AD30),25) -> #DIV/0! | AF30: =CEILING(IF(OR($R30="ISO 6",$R30="GRADE B",$R30="1K",$R30=1000),AE30*1/175,IF(OR($R30="ISO 5",$R30="GRADE A",$R30=100),AE30*1/100,IF(OR($R30="ISO 7",$R30="GRADE C",$R30="10K",$R30=10000),$AE30*1/250,IF(OR($R30="ISO 8",$R30="GRADE D",$R30="100K",$R30=100000),$AE30*1/250,IF(OR($R30="NC",$R30="20 Micron",$R30="5 Micron",$R30="N C"),$AE30*1/350,0))))),2) -> #DIV/0! | AG30: =IF(ISNUMBER(N30), CEILING(MAX(AI30,AJ30),0.5), "Ambient") -> #DIV/0! | AH30: C | AI30: =IF(ISNUMBER(N30), CEILING(CE30/12000,0.5), "Ambient") -> 0 | AJ30: =IF(ISNUMBER(N30),CEILING(AE30/(IF(AH30="C",400,300)),0.5), "Ambient") -> #DIV/0! | AK30: =CEILING(SUM(AE30:AE45),250) -> #DIV/0! | AL30: W | AM30: 150 | AN30: =IF(AK30<=1300,200,IF(AK30<=1600,225,IF(AK30<=2100,250,IF(AK30<=2700,280,IF(AK30<=3450,315,IF(AK30<=4250,355,IF(AK30<=5250,400,IF(AK30<=6750,450,IF(AK30<=8500,500,IF(AK30<=10750,560,IF(AK30<=13500,630,IF(AK30<=17000,710,IF(AK30<=21500,800,IF(AK30<=27000,900,IF(AK30<=34000,1000,IF(AK30<=43000,1120,IF(AK30<=49000,1200,IF(AK30<=68000,1450,"Refer")))))))))))))))))) -> #DIV/0! | AO30: =IF(AK30*AM30/(6356*0.7*0.9*1.1*25.4)<=1,1,IF(AK30*AM30/(6356*0.7*0.9*1.1*25.4)<=1.5,1.5,IF(AK30*AM30/(6356*0.7*0.9*1.1*25.4)<=2,2,IF(AK30*AM30/(6356*0.7*0.9*1.1*25.4)<=3,3,IF(AK30*AM30/(6356*0.7*0.9*1.1*25.4)<=5,5,IF(AK30*AM30/(6356*0.7*0.9*1.1*25.4)<=7.5,7.5,IF(AK30*AM30/(6356*0.7*0.9*1.1*25.4)<=10,10,IF(AK30*AM30/(6356*0.7*0.9*1.1*25.4)<=12.5,12.5,IF(AK30*AM30/(6356*0.7*0.9*1.1*25.4)<=15,15,IF(AK30*AM30/(6356*0.7*0.9*1.1*25.4)<=20,20,IF(AK30*AM30/(6356*0.7*0.9*1.1*25.4)<=25,25,IF(AK30*AM30/(6356*0.7*0.9*1.1*25.4)<=30,30,IF(AK30*AM30/(6356*0.7*0.9*1.1*25.4)<=40,40,IF(AK30*AM30/(6356*0.7*0.9*1.1*25.4)<=50,50,IF(AK30*AM30/(6356*0.7*0.9*1.1*25.4)<=60,60,IF(AK30*AM30/(6356*0.7*0.9*1.1*25.4)<=75,75,"Refer")))))))))))))))) -> #DIV/0! | AP30: =IF(AND(AQ30=0, N30="Amb"), "Amb",IF((AL31-250)*(AL33-150)*10.76/(1000*1000) >= MAX(AI46,AJ46), 4,IF((AL31-250)*(AL33-150)*10.76*1.5/(1000*1000) >= MAX(AI46,AJ46), 6,IF((AL31-250)*(AL33-150)*10.76*2/(1000*1000) >= MAX(AI46,AJ46), 8, 0)) ) ) -> #DIV/0! | AQ30: =AG46 -> #DIV/0! | AR30: =_xlfn.SWITCH(TRIM(UPPER(R30)),"ISO 9", 3,"ISO 8", 4,"Grade D", 4,"Class 100,000", 4,"Class 100K", 4,"ISO 7", 3,"Grade C", 3,"Class 10,000", 3,"Class 10K", 3,"ISO 6", 3,"Class 1,000", 3,"Class 1K", 3,"ISO 5", 4,"Grade A", 4,"Grade B", 4,"Class 100", 4,"ISO 4", 3,"ISO 3", 4,"ISO 2", 4,"ISO 1", 4,"NCV20",1,"NCV-10",2,"NCV-5",3,"NCAC-10",1,"NCAC-5",2,"NCAC-1",3,3) -> 3 | AS30: =MAX(AI46,AJ46)*24/6 -> #DIV/0! | AT30: =AS30*0.06309 -> #DIV/0! | AU30: 2 | AV30: =SQRT((4*AS30*0.00006309)/(3.14*AU30))*1000 -> #DIV/0!
C31: =IF(D31<>"",COUNTA($D$10:D31),"") -> 19 | D31: Clean Room 11 | E31: 1.8 | F31: 2.2 | G31: 2.4 | H31: 2 | I31: 1 | J31: 1.75 | K31: 3 | L31: 0.1 | M31: 0 | N31: 24 | O31: 50 | P31: 45 | Q31: 85 | R31: ISO 6 | S31: 160 | T31: 0 | U31: 100 | V31: =R31 -> ISO 6 | W31: =S31 -> 160 | X31: =E31*F31*10.76 -> 42.6096 | Y31: =X31*G31*3.28 -> 335.42277 | Z31: =Y31*S31/60 -> 894.46072 | AA31: =Z31*L31 -> 89.446072 | AB31: =IF(N31="Amb",Z31,Z31*M31) -> 0 | AC31: =IF(ISNUMBER(N31), (AA31*0.075*60/2.20462)*BP31/7000, "Ambient") -> 0 | AD31: =IF(ISNUMBER(N31), CEILING(CF31/(0.68*BP31),25), "Ambient") -> #DIV/0! | AE31: =CEILING(MAX((Z31+AA31),AD31),25) -> #DIV/0! | AF31: =CEILING(IF(OR($R31="ISO 6",$R31="GRADE B",$R31="1K",$R31=1000),AE31*1/175,IF(OR($R31="ISO 5",$R31="GRADE A",$R31=100),AE31*1/100,IF(OR($R31="ISO 7",$R31="GRADE C",$R31="10K",$R31=10000),$AE31*1/250,IF(OR($R31="ISO 8",$R31="GRADE D",$R31="100K",$R31=100000),$AE31*1/250,IF(OR($R31="NC",$R31="20 Micron",$R31="5 Micron",$R31="N C"),$AE31*1/350,0))))),2) -> #DIV/0! | AG31: =IF(ISNUMBER(N31), CEILING(MAX(AI31,AJ31),0.5), "Ambient") -> #DIV/0! | AH31: C | AI31: =IF(ISNUMBER(N31), CEILING(CE31/12000,0.5), "Ambient") -> 0 | AJ31: =IF(ISNUMBER(N31),CEILING(AE31/(IF(AH31="C",400,300)),0.5), "Ambient") -> #DIV/0! | AL31: =IF(AK30<=2000,950,(IF(AK30<=3000,1150,(IF(AK30<=8000,1550,(IF(AK30<=10000,1750,(IF(AK30<=18000,2050,(IF(AK30<=32000,2900,(IF(AK30<=40000,3600,4000))))))))))))) -> #DIV/0!
C32: =IF(D32<>"",COUNTA($D$10:D32),"") -> 20 | D32: Clean Room 12 | E32: 1.5 | F32: 2.8 | G32: 2.4 | H32: 2 | I32: 3 | J32: 1.75 | K32: 3 | L32: 0.1 | M32: 0 | N32: 24 | O32: 50 | P32: 45 | Q32: 85 | R32: ISO 6 | S32: 160 | T32: 0 | U32: 100 | V32: =R32 -> ISO 6 | W32: =S32 -> 160 | X32: =E32*F32*10.76 -> 45.192 | Y32: =X32*G32*3.28 -> 355.75142 | Z32: =Y32*S32/60 -> 948.67046 | AA32: =Z32*L32 -> 94.867046 | AB32: =IF(N32="Amb",Z32,Z32*M32) -> 0 | AC32: =IF(ISNUMBER(N32), (AA32*0.075*60/2.20462)*BP32/7000, "Ambient") -> 0 | AD32: =IF(ISNUMBER(N32), CEILING(CF32/(0.68*BP32),25), "Ambient") -> #DIV/0! | AE32: =CEILING(MAX((Z32+AA32),AD32),25) -> #DIV/0! | AF32: =CEILING(IF(OR($R32="ISO 6",$R32="GRADE B",$R32="1K",$R32=1000),AE32*1/175,IF(OR($R32="ISO 5",$R32="GRADE A",$R32=100),AE32*1/100,IF(OR($R32="ISO 7",$R32="GRADE C",$R32="10K",$R32=10000),$AE32*1/250,IF(OR($R32="ISO 8",$R32="GRADE D",$R32="100K",$R32=100000),$AE32*1/250,IF(OR($R32="NC",$R32="20 Micron",$R32="5 Micron",$R32="N C"),$AE32*1/350,0))))),2) -> #DIV/0! | AG32: =IF(ISNUMBER(N32), CEILING(MAX(AI32,AJ32),0.5), "Ambient") -> #DIV/0! | AH32: C | AI32: =IF(ISNUMBER(N32), CEILING(CE32/12000,0.5), "Ambient") -> 0 | AJ32: =IF(ISNUMBER(N32),CEILING(AE32/(IF(AH32="C",400,300)),0.5), "Ambient") -> #DIV/0! | AL32: H
C33: =IF(D33<>"",COUNTA($D$10:D33),"") -> 21 | D33: Clean Room 13 | E33: 2.1 | F33: 3.5 | G33: 2.4 | H33: 0 | I33: 1 | J33: 1.75 | K33: 3 | L33: 0.1 | M33: 0 | N33: 24 | O33: 50 | P33: 45 | Q33: 85 | R33: ISO 6 | S33: 160 | T33: 0 | U33: 100 | V33: =R33 -> ISO 6 | W33: =S33 -> 160 | X33: =E33*F33*10.76 -> 79.086 | Y33: =X33*G33*3.28 -> 622.56499 | Z33: =Y33*S33/60 -> 1660.1733 | AA33: =Z33*L33 -> 166.01733 | AB33: =IF(N33="Amb",Z33,Z33*M33) -> 0 | AC33: =IF(ISNUMBER(N33), (AA33*0.075*60/2.20462)*BP33/7000, "Ambient") -> 0 | AD33: =IF(ISNUMBER(N33), CEILING(CF33/(0.68*BP33),25), "Ambient") -> #DIV/0! | AE33: =CEILING(MAX((Z33+AA33),AD33),25) -> #DIV/0! | AF33: =CEILING(IF(OR($R33="ISO 6",$R33="GRADE B",$R33="1K",$R33=1000),AE33*1/175,IF(OR($R33="ISO 5",$R33="GRADE A",$R33=100),AE33*1/100,IF(OR($R33="ISO 7",$R33="GRADE C",$R33="10K",$R33=10000),$AE33*1/250,IF(OR($R33="ISO 8",$R33="GRADE D",$R33="100K",$R33=100000),$AE33*1/250,IF(OR($R33="NC",$R33="20 Micron",$R33="5 Micron",$R33="N C"),$AE33*1/350,0))))),2) -> #DIV/0! | AG33: =IF(ISNUMBER(N33), CEILING(MAX(AI33,AJ33),0.5), "Ambient") -> #DIV/0! | AH33: C | AI33: =IF(ISNUMBER(N33), CEILING(CE33/12000,0.5), "Ambient") -> 0 | AJ33: =IF(ISNUMBER(N33),CEILING(AE33/(IF(AH33="C",400,300)),0.5), "Ambient") -> #DIV/0! | AL33: =IF(AK30<=2000,950,(IF(AK30<=4000,1100,(IF(AK30<=6000,1250,(IF(AK30<=10000,1550,(IF(AK30<=15000,1750,(IF(AK30<=24000,2050,(IF(AK30<=40000,2900,3600))))))))))))) -> #DIV/0!
C34: =IF(D34<>"",COUNTA($D$10:D34),"") -> 22 | D34: Clean Room 14 | E34: 2.7 | F34: 4 | G34: 2.4 | H34: 2 | I34: 1 | J34: 1.75 | K34: 3 | L34: 0.1 | M34: 0 | N34: 24 | O34: 50 | P34: 45 | Q34: 85 | R34: ISO 6 | S34: 160 | T34: 0 | U34: 100 | V34: =R34 -> ISO 6 | W34: =S34 -> 160 | X34: =E34*F34*10.76 -> 116.208 | Y34: =X34*G34*3.28 -> 914.78938 | Z34: =Y34*S34/60 -> 2439.4383 | AA34: =Z34*L34 -> 243.94383 | AB34: =IF(N34="Amb",Z34,Z34*M34) -> 0 | AC34: =IF(ISNUMBER(N34), (AA34*0.075*60/2.20462)*BP34/7000, "Ambient") -> 0 | AD34: =IF(ISNUMBER(N34), CEILING(CF34/(0.68*BP34),25), "Ambient") -> #DIV/0! | AE34: =CEILING(MAX((Z34+AA34),AD34),25) -> #DIV/0! | AF34: =CEILING(IF(OR($R34="ISO 6",$R34="GRADE B",$R34="1K",$R34=1000),AE34*1/175,IF(OR($R34="ISO 5",$R34="GRADE A",$R34=100),AE34*1/100,IF(OR($R34="ISO 7",$R34="GRADE C",$R34="10K",$R34=10000),$AE34*1/250,IF(OR($R34="ISO 8",$R34="GRADE D",$R34="100K",$R34=100000),$AE34*1/250,IF(OR($R34="NC",$R34="20 Micron",$R34="5 Micron",$R34="N C"),$AE34*1/350,0))))),2) -> #DIV/0! | AG34: =IF(ISNUMBER(N34), CEILING(MAX(AI34,AJ34),0.5), "Ambient") -> #DIV/0! | AH34: C | AI34: =IF(ISNUMBER(N34), CEILING(CE34/12000,0.5), "Ambient") -> 0 | AJ34: =IF(ISNUMBER(N34),CEILING(AE34/(IF(AH34="C",400,300)),0.5), "Ambient") -> #DIV/0! | AL34: L
C35: =IF(D35<>"",COUNTA($D$10:D35),"") -> 23 | D35: Clean Room 15 | E35: 3.8 | F35: 4.2 | G35: 2.4 | H35: 3 | I35: 3 | J35: 1.75 | K35: 3 | L35: 0.1 | M35: 0 | N35: 24 | O35: 50 | P35: 45 | Q35: 85 | R35: ISO 6 | S35: 160 | T35: 0 | U35: 100 | V35: =R35 -> ISO 6 | W35: =S35 -> 160 | X35: =E35*F35*10.76 -> 171.7296 | Y35: =X35*G35*3.28 -> 1351.8554 | Z35: =Y35*S35/60 -> 3604.9478 | AA35: =Z35*L35 -> 360.49478 | AB35: =IF(N35="Amb",Z35,Z35*M35) -> 0 | AC35: =IF(ISNUMBER(N35), (AA35*0.075*60/2.20462)*BP35/7000, "Ambient") -> 0 | AD35: =IF(ISNUMBER(N35), CEILING(CF35/(0.68*BP35),25), "Ambient") -> #DIV/0! | AE35: =CEILING(MAX((Z35+AA35),AD35),25) -> #DIV/0! | AF35: =CEILING(IF(OR($R35="ISO 6",$R35="GRADE B",$R35="1K",$R35=1000),AE35*1/175,IF(OR($R35="ISO 5",$R35="GRADE A",$R35=100),AE35*1/100,IF(OR($R35="ISO 7",$R35="GRADE C",$R35="10K",$R35=10000),$AE35*1/250,IF(OR($R35="ISO 8",$R35="GRADE D",$R35="100K",$R35=100000),$AE35*1/250,IF(OR($R35="NC",$R35="20 Micron",$R35="5 Micron",$R35="N C"),$AE35*1/350,0))))),2) -> #DIV/0! | AG35: =IF(ISNUMBER(N35), CEILING(MAX(AI35,AJ35),0.5), "Ambient") -> #DIV/0! | AH35: C | AI35: =IF(ISNUMBER(N35), CEILING(CE35/12000,0.5), "Ambient") -> 0 | AJ35: =IF(ISNUMBER(N35),CEILING(AE35/(IF(AH35="C",400,300)),0.5), "Ambient") -> #DIV/0! | AL35: =IF(AL39<4000,AL39,AL39+400) -> #DIV/0!
C36: =IF(D36<>"",COUNTA($D$10:D36),"") -> 24 | D36: Clean Room 16 | E36: 3.1 | F36: 2.6 | G36: 2.4 | H36: 2 | I36: 1 | J36: 1.75 | K36: 3 | L36: 0.1 | M36: 0 | N36: 24 | O36: 50 | P36: 45 | Q36: 85 | R36: ISO 6 | S36: 160 | T36: 0 | U36: 100 | V36: =R36 -> ISO 6 | W36: =S36 -> 160 | X36: =E36*F36*10.76 -> 86.7256 | Y36: =X36*G36*3.28 -> 682.70392 | Z36: =Y36*S36/60 -> 1820.5438 | AA36: =Z36*L36 -> 182.05438 | AB36: =IF(N36="Amb",Z36,Z36*M36) -> 0 | AC36: =IF(ISNUMBER(N36), (AA36*0.075*60/2.20462)*BP36/7000, "Ambient") -> 0 | AD36: =IF(ISNUMBER(N36), CEILING(CF36/(0.68*BP36),25), "Ambient") -> #DIV/0! | AE36: =CEILING(MAX((Z36+AA36),AD36),25) -> #DIV/0! | AF36: =CEILING(IF(OR($R36="ISO 6",$R36="GRADE B",$R36="1K",$R36=1000),AE36*1/175,IF(OR($R36="ISO 5",$R36="GRADE A",$R36=100),AE36*1/100,IF(OR($R36="ISO 7",$R36="GRADE C",$R36="10K",$R36=10000),$AE36*1/250,IF(OR($R36="ISO 8",$R36="GRADE D",$R36="100K",$R36=100000),$AE36*1/250,IF(OR($R36="NC",$R36="20 Micron",$R36="5 Micron",$R36="N C"),$AE36*1/350,0))))),2) -> #DIV/0! | AG36: =IF(ISNUMBER(N36), CEILING(MAX(AI36,AJ36),0.5), "Ambient") -> #DIV/0! | AH36: C | AI36: =IF(ISNUMBER(N36), CEILING(CE36/12000,0.5), "Ambient") -> 0 | AJ36: =IF(ISNUMBER(N36),CEILING(AE36/(IF(AH36="C",400,300)),0.5), "Ambient") -> #DIV/0!
C37: =IF(D37<>"",COUNTA($D$10:D37),"") -> 25 | D37: Clean Room 17 | E37: 1.9 | F37: 2.4 | G37: 2.4 | H37: 3 | I37: 2 | J37: 1.75 | K37: 3 | L37: 0.1 | M37: 0 | N37: 24 | O37: 50 | P37: 45 | Q37: 85 | R37: ISO 6 | S37: 160 | T37: 0 | U37: 100 | V37: =R37 -> ISO 6 | W37: =S37 -> 160 | X37: =E37*F37*10.76 -> 49.0656 | Y37: =X37*G37*3.28 -> 386.2444 | Z37: =Y37*S37/60 -> 1029.9851 | AA37: =Z37*L37 -> 102.99851 | AB37: =IF(N37="Amb",Z37,Z37*M37) -> 0 | AC37: =IF(ISNUMBER(N37), (AA37*0.075*60/2.20462)*BP37/7000, "Ambient") -> 0 | AD37: =IF(ISNUMBER(N37), CEILING(CF37/(0.68*BP37),25), "Ambient") -> #DIV/0! | AE37: =CEILING(MAX((Z37+AA37),AD37),25) -> #DIV/0! | AF37: =CEILING(IF(OR($R37="ISO 6",$R37="GRADE B",$R37="1K",$R37=1000),AE37*1/175,IF(OR($R37="ISO 5",$R37="GRADE A",$R37=100),AE37*1/100,IF(OR($R37="ISO 7",$R37="GRADE C",$R37="10K",$R37=10000),$AE37*1/250,IF(OR($R37="ISO 8",$R37="GRADE D",$R37="100K",$R37=100000),$AE37*1/250,IF(OR($R37="NC",$R37="20 Micron",$R37="5 Micron",$R37="N C"),$AE37*1/350,0))))),2) -> #DIV/0! | AG37: =IF(ISNUMBER(N37), CEILING(MAX(AI37,AJ37),0.5), "Ambient") -> #DIV/0! | AH37: C | AI37: =IF(ISNUMBER(N37), CEILING(CE37/12000,0.5), "Ambient") -> 0 | AJ37: =IF(ISNUMBER(N37),CEILING(AE37/(IF(AH37="C",400,300)),0.5), "Ambient") -> #DIV/0!
C38: =IF(D38<>"",COUNTA($D$10:D38),"") -> 26 | D38: Clean Room 18 | E38: 3 | F38: 2.9 | G38: 2.4 | H38: 2 | I38: 1 | J38: 1.75 | K38: 3 | L38: 0.1 | M38: 0 | N38: 24 | O38: 50 | P38: 45 | Q38: 85 | R38: ISO 6 | S38: 160 | T38: 0 | U38: 100 | V38: =R38 -> ISO 6 | W38: =S38 -> 160 | X38: =E38*F38*10.76 -> 93.612 | Y38: =X38*G38*3.28 -> 736.91366 | Z38: =Y38*S38/60 -> 1965.1031 | AA38: =Z38*L38 -> 196.51031 | AB38: =IF(N38="Amb",Z38,Z38*M38) -> 0 | AC38: =IF(ISNUMBER(N38), (AA38*0.075*60/2.20462)*BP38/7000, "Ambient") -> 0 | AD38: =IF(ISNUMBER(N38), CEILING(CF38/(0.68*BP38),25), "Ambient") -> #DIV/0! | AE38: =CEILING(MAX((Z38+AA38),AD38),25) -> #DIV/0! | AF38: =CEILING(IF(OR($R38="ISO 6",$R38="GRADE B",$R38="1K",$R38=1000),AE38*1/175,IF(OR($R38="ISO 5",$R38="GRADE A",$R38=100),AE38*1/100,IF(OR($R38="ISO 7",$R38="GRADE C",$R38="10K",$R38=10000),$AE38*1/250,IF(OR($R38="ISO 8",$R38="GRADE D",$R38="100K",$R38=100000),$AE38*1/250,IF(OR($R38="NC",$R38="20 Micron",$R38="5 Micron",$R38="N C"),$AE38*1/350,0))))),2) -> #DIV/0! | AG38: =IF(ISNUMBER(N38), CEILING(MAX(AI38,AJ38),0.5), "Ambient") -> #DIV/0! | AH38: C | AI38: =IF(ISNUMBER(N38), CEILING(CE38/12000,0.5), "Ambient") -> 0 | AJ38: =IF(ISNUMBER(N38),CEILING(AE38/(IF(AH38="C",400,300)),0.5), "Ambient") -> #DIV/0!
